Workbook
Name _?frequency_1mo_period1_1614793098_period2_1772559485: Beta!$A$1:$B$62

Sheet Balance Sheet
A2: Particulars | C2: 2021 | D2: 2022 | E2: 2023 | F2: 2024 | G2: 2025 | H2: =G2+1 -> 2026 | I2: =H2+1 -> 2027 | J2: =I2+1 -> 2028 | K2: =J2+1 -> 2029 | L2: =K2+1 -> 2030
A4: Assets
A5: Non-current assets
A6: (a) Property, plant and equipment | C6: 1897 | D6: 3233.41 | E6: 4696.94 | F6: 4677.03 | G6: 4842.39 | H6: =Notes!G17 -> 5250.4507 | I6: =Notes!H17 -> 5634.3044 | J6: =Notes!I17 -> 5977.186 | K6: =Notes!J17 -> 6461.8669 | L6: =Notes!K17 -> 6868.234
A7: (b) Capital work-in-progress | C7: 226.81 | D7: 423.18 | E7: 203.13 | F7: 147.3 | G7: 1525.48 | H7: 1525.48 | I7: 1525.48 | J7: 1525.48 | K7: 1525.48 | L7: 1525.48
A8: (c) Right-of- use assets | C8: 1210.79 | D8: 1783.51 | E8: 1826.45 | F8: 1557.51 | G8: 1623.93 | H8: =Notes!G57 -> 1539.3869 | I8: =Notes!H57 -> 1440.4952 | J8: =Notes!I57 -> 1293.8479 | K8: =Notes!J57 -> 1193.781 | L8: =Notes!K57 -> 1135.4043
A9: (d) Goodwill | C9: 2033.63 | D9: 1227.03 | E9: 2060.77 | F9: 2060.77 | G9: 2060.77 | H9: 2060.77 | I9: 2060.77 | J9: 2060.77 | K9: 2060.77 | L9: 2060.77
A10: (e) Other intangible assets | C10: 189.54 | D10: 128.38 | E10: 109.15 | F10: 63.51 | G10: 46.41 | H10: =Notes!G37 -> 45.068 | I10: =Notes!H37 -> 41.036 | J10: =Notes!I37 -> 34.304 | K10: =Notes!J37 -> 24.872 | L10: =Notes!K37 -> 12.74
A11: (f) Intangible assets under development | C11: 4.66 | D11: 1.02 | E11: 0.24 | F11: 33.91 | G11: 119.38 | H11: 119.38 | I11: 119.38 | J11: 119.38 | K11: 119.38 | L11: 119.38
A12: (g) Financial assets
A13: (i) Investments | C13: 0.08 | D13: 1882.48 | E13: 337.55 | F13: 600.08 | G13: 1255.08 | H13: =G13-'Cash Flows'!G41 -> 1755.08 | I13: =H13-'Cash Flows'!H41 -> 2355.08 | J13: =I13-'Cash Flows'!I41 -> 3055.08 | K13: =J13-'Cash Flows'!J41 -> 3855.08 | L13: =K13-'Cash Flows'!K41 -> 4755.08
A14: (ii) Other financials etsas | C14: 259.06 | D14: 280.27 | E14: 318.8 | F14: 480.8 | G14: 795.34 | H14: 795.34 | I14: 795.34 | J14: 795.34 | K14: 795.34 | L14: 795.34
A15: (h) Deferred tax assets (net) | C15: 247.83 | D15: 177.47 | E15: 368.6 | F15: 390.33 | G15: 398.61 | H15: 398.61 | I15: 398.61 | J15: 398.61 | K15: 398.61 | L15: 398.61
A16: (i) Income tax as sets (net) | C16: 99.34 | D16: 220.33 | E16: 196.28 | F16: 205.89 | G16: 76.67 | H16: 76.67 | I16: 76.67 | J16: 76.67 | K16: 76.67 | L16: 76.67
A17: (j) Other non-current assets | C17: 146.11 | D17: 210.03 | E17: 112.15 | F17: 186.85 | G17: 364.88 | H17: =364.88 -> 364.88 | I17: 364.88 | J17: 364.88 | K17: 364.88 | L17: 364.88
A18: Total non-current assets | C18: =SUM(C6:C17) -> 6314.85 | D18: =SUM(D6:D17) -> 9567.11 | E18: =SUM(E6:E17) -> 10230.06 | F18: =SUM(F6:F17) -> 10403.98 | G18: =SUM(G6:G17) -> 13108.94 | H18: =SUM(H6:H17) -> 13931.116 | I18: =SUM(I6:I17) -> 14812.046 | J18: =SUM(J6:J17) -> 15701.548 | ... L18: =SUM(L6:L17) -> 18112.588
A19: Current assets
A20: (a) Inventories | C20: 894.73 | D20: 629.27 | E20: 741.7 | F20: 1268.6 | G20: 795.83 | H20: =Ratios!I10 -> 671.08432 | I20: =Ratios!J10 -> 1097.672 | J20: =Ratios!K10 -> 884.72572 | K20: =Ratios!L10 -> 1337.6146 | L20: =Ratios!M10 -> 1154.2482
A21: (b) Financial assets
A22: (i) Investments | C22: 1122.55 | D22: 780.74 | E22: 2454.89 | F22: 4251.32 | G22: 4908.03 | H22: =G22-'Cash Flows'!G41 -> 5408.03 | I22: =H22-'Cash Flows'!H41 -> 6008.03 | J22: =I22-'Cash Flows'!I41 -> 6708.03 | K22: =J22-'Cash Flows'!J41 -> 7508.03 | L22: =K22-'Cash Flows'!K41 -> 8408.03
A23: (ii) Trade receivables | C23: 5007.19 | D23: 4269.95 | E23: 5260.03 | F23: 7197.13 | G23: 8145.55 | H23: =Ratios!I24-Notes!Q8 -> 5770.5979 | I23: =Ratios!J24-Notes!R8 -> 11065.894 | J23: =Ratios!K24-Notes!S8 -> 7787.34 | K23: =Ratios!L24-Notes!T8 -> 13331.198 | L23: =Ratios!M24-Notes!U8 -> 10332.214
A24: (iii) Cash and cash equiv alents | C24: 1335.14 | D24: 396.74 | E24: 963.14 | F24: 1590.08 | G24: 2308.52 | H24: ='Cash Flows'!G61 -> 6756.1704 | I24: ='Cash Flows'!H61 -> 4642.2408 | J24: ='Cash Flows'!I61 -> 10830.324 | K24: ='Cash Flows'!J61 -> 10035.741 | L24: ='Cash Flows'!K61 -> 17472.041
A25: (iv) Bank balanc es other than (iii) abo ve | C25: 610.34 | D25: 559.3 | E25: 599.38 | F25: 1080.06 | G25: 648.03 | H25: 648.03 | I25: 648.03 | J25: 648.03 | K25: 648.03 | L25: 648.03
A26: (v)Loan | D26: 143.86 | E26: - | F26: - | G26: -
A27: (v) Other financial assets | C27: 40.89 | D27: 259.09 | E27: 29.62 | F27: 98.52 | G27: 481.69 | H27: 481.69 | I27: 481.69 | J27: 481.69 | K27: 481.69 | L27: 481.69
A28: (c) Other current assets | C28: 792.41 | D28: 1007.88 | E28: 733.44 | F28: 695.55 | G28: 802.65 | H28: 802.65 | I28: 802.65 | J28: 802.65 | K28: 802.65 | L28: 802.65
A29: Total current assets | C29: =SUM(C20:C28) -> 9803.25 | D29: =SUM(D20:D28) -> 8046.83 | E29: =SUM(E20:E28) -> 10782.2 | F29: =SUM(F20:F28) -> 16181.26 | G29: =SUM(G20:G28) -> 18090.3 | H29: =SUM(H20:H28) -> 20538.253 | I29: =SUM(I20:I28) -> 24746.207 | J29: =SUM(J20:J28) -> 28142.79 | ... L29: =SUM(L20:L28) -> 39298.903
A31: Total Assets | B31: 13327.38 | C31: =C29+C18 -> 16118.1 | D31: =D29+D18 -> 17613.94 | E31: =E29+E18 -> 21012.26 | F31: =F29+F18 -> 26585.24 | G31: =G29+G18 -> 31199.24 | H31: =H29+H18 -> 34469.368 | I31: =I29+I18 -> 39558.252 | J31: =J29+J18 -> 43844.338 | ... L31: =L29+L18 -> 57411.492
A33: Equity and Liabilities
A35: Equity
A36: a) Equity share capital | C36: 1480 | D36: 1531.53 | E36: 1544 | F36: 1627.62 | G36: 1643.65 | H36: 1643.65 | I36: 1643.65 | J36: 1643.65 | K36: 1643.65 | L36: 1643.65
A37: b) Other equity | C37: 8364.76 | D37: 10587.57 | E37: 14080.55 | F37: 17839.97 | G37: 21021.49 | H37: =G37+'Income Statement '!G91+'Cash Flows'!G23 -> 23945.696 | I37: =H37+'Income Statement '!H91+'Cash Flows'!H23 -> 27703.62 | J37: =I37+'Income Statement '!I91+'Cash Flows'!I23 -> 31880.29 | K37: =J37+'Income Statement '!J91+'Cash Flows'!J23 -> 36581.409 | L37: =K37+'Income Statement '!K91+'Cash Flows'!K23 -> 41881.904
A38: Total Equity attributable to Equity Share holders | B38: 8503.91 | C38: =SUM(C36:C37) -> 9844.76 | D38: =SUM(D36:D37) -> 12119.1 | E38: =SUM(E36:E37) -> 15624.55 | F38: =SUM(F36:F37) -> 19467.59 | G38: =SUM(G36:G37) -> 22665.14 | H38: =SUM(H36:H37) -> 25589.346 | I38: =SUM(I36:I37) -> 29347.27 | J38: =SUM(J36:J37) -> 33523.94 | ... L38: =SUM(L36:L37) -> 43525.554
A39: Liabilities
A40: Non-current liabilities
A41: a) Financial liabiltiies
A42: (i) Lease liabilities | B42: 633.66 | C42: 945.38 | D42: 1458.24 | E42: 1528.03 | F42: 1281.14 | G42: 1320.54 | H42: =Notes!G63*0.73 -> 1307.1011 | I42: =Notes!H63*0.73 -> 1338.8845 | J42: =Notes!I63*0.73 -> 1312.2986 | K42: =Notes!J63*0.73 -> 1316.0778 | L42: =Notes!K63*0.73 -> 1292.2553
A43: b) Provisions | C43: 191.01 | D43: 24.79 | E43: 211.12 | F43: 239.27 | G43: 253.88 | H43: ='Key Indicator'!G288 -> 253.88 | I43: ='Key Indicator'!H288 -> 253.88 | J43: ='Key Indicator'!I288 -> 253.88 | K43: ='Key Indicator'!J288 -> 253.88 | L43: ='Key Indicator'!K288 -> 253.88
A44: c) Other non current liabilities | D44: 9.25 | E44: 6.14 | F44: 81.54 | G44: 58.98 | H44: 58.98 | I44: 58.98 | J44: 58.98 | K44: 58.98 | L44: 58.98
A45: Total Non-current liabilities | C45: =SUM(C42:C44) -> 1136.39 | D45: =SUM(D42:D44) -> 1492.28 | E45: =SUM(E42:E44) -> 1745.29 | F45: =SUM(F42:F44) -> 1601.95 | G45: =SUM(G42:G44) -> 1633.4 | H45: =SUM(H42:H44) -> 1619.9611 | I45: =SUM(I42:I44) -> 1651.7445 | J45: =SUM(J42:J44) -> 1625.1586 | ... L45: =SUM(L42:L44) -> 1605.1153
...

Sheet Income Statement 
A2: Particulars | B2: 2021 | C2: =B2+1 -> 2022 | D2: =C2+1 -> 2023 | E2: =D2+1 -> 2024 | F2: =E2+1 -> 2025 | G2: =F2+1 -> 2026 | H2: =G2+1 -> 2027 | I2: =H2+1 -> 2028 | J2: =I2+1 -> 2029 | K2: =J2+1 -> 2030
A4: Revenue from operations | B4: 13060.9 | C4: 15896.71 | D4: 19147.3 | E4: 22646.77 | F4: 24245.32 | G4: ='Revenue Forecasting '!H22 -> 25457.586 | H4: ='Revenue Forecasting '!I22 -> 30695.907 | I4: ='Revenue Forecasting '!J22 -> 34403.55 | J4: ='Revenue Forecasting '!K22 -> 38567.638 | K4: ='Revenue Forecasting '!L22 -> 43245.069
A5: Growth | C5: =(C4/B4)-1 -> 0.2171221 | D5: =(D4/C4)-1 -> 0.20448193 | E5: =(E4/D4)-1 -> 0.18276572 | F5: =(F4/E4)-1 -> 0.070586225 | G5: =(G4/F4)-1 -> 0.05 | H5: =(H4/G4)-1 -> 0.2057666 | I5: =(I4/H4)-1 -> 0.12078623 | J5: =(J4/I4)-1 -> 0.12103659 | K5: =(K4/J4)-1 -> 0.12127866
A6: Total Revenue | B6: =B4 -> 13060.9 | C6: =C4 -> 15896.71 | D6: =D4 -> 19147.3 | E6: =E4 -> 22646.77 | F6: =F4 -> 24245.32 | G6: =G4 -> 25457.586 | H6: =H4 -> 30695.907 | I6: =I4 -> 34403.55 | ... K6: =K4 -> 43245.069
A8: COGS
A9: Purchase of traded goods | B9: 2069.54 | C9: 1360.86 | D9: 1132.07 | E9: 2515.68 | F9: 1953.68 | G9: =F9/F$16*G$16 -> 2175.421 | H9: =G9/G$16*H$16 -> 2623.05 | I9: =H9/H$16*I$16 -> 2939.8783 | J9: =I9/I$16*J$16 -> 3295.7112 | K9: =J9/J$16*K$16 -> 3695.4106
A10: Service and security charges | B10: 3172.79 | C10: 3207.18 | D10: 3815.65 | E10: 4493.14 | F10: 4818.56 | G10: =F10/F$16*G$16 -> 5365.4625 | H10: =G10/G$16*H$16 -> 6469.4954 | I10: =H10/H$16*I$16 -> 7250.9214 | J10: =I10/I$16*J$16 -> 8128.5481 | K10: =J10/J$16*K$16 -> 9114.3676
A11: Vehicle maintenance, hire and fuel cost | B11: 861.22 | C11: 1508.78 | D11: 1584.29 | E11: 1641.35 | F11: 1821.66 | G11: =F11/F$16*G$16 -> 2028.4169 | H11: =G11/G$16*H$16 -> 2445.7973 | I11: =H11/H$16*I$16 -> 2741.2159 | J11: =I11/I$16*J$16 -> 3073.0033 | K11: =J11/J$16*K$16 -> 3445.6931
A12: Conveyance and traveling expenses | B12: 465.24 | C12: 770.14 | D12: 952.45 | E12: 1075.63 | F12: 1065.02 | G12: =F12/F$16*G$16 -> 1185.8989 | H12: =G12/G$16*H$16 -> 1429.9172 | I12: =H12/H$16*I$16 -> 1602.6316 | J12: =I12/I$16*J$16 -> 1796.6086 | K12: =J12/J$16*K$16 -> 2014.4989
A13: Power and electricity charges | B13: 80.54 | C13: 112.81 | D13: 195.05 | E13: 218.12 | F13: 202.49 | G13: =F13/F$16*G$16 -> 225.47244 | H13: =G13/G$16*H$16 -> 271.86714 | I13: =H13/H$16*I$16 -> 304.70495 | J13: =I13/I$16*J$16 -> 341.58539 | K13: =J13/J$16*K$16 -> 383.01241
A14: Cash lost in transit | B14: 75.09 | C14: 66.68 | D14: 41.85 | E14: 87.44 | F14: 101.26 | G14: =F14/F$16*G$16 -> 112.75292 | H14: =G14/G$16*H$16 -> 135.95371 | I14: =H14/H$16*I$16 -> 152.37505 | J14: =I14/I$16*J$16 -> 170.818 | K14: =J14/J$16*K$16 -> 191.53458
A15: Cash disposal charges | B15: 156.01 | C15: 139.22 | D15: 211.93 | E15: 226.6 | F15: 433.64 | G15: =F15/F$16*G$16 -> 482.85777 | H15: =G15/G$16*H$16 -> 582.21377 | I15: =H15/H$16*I$16 -> 652.53718 | J15: =I15/I$16*J$16 -> 731.51805 | K15: =J15/J$16*K$16 -> 820.23558
A16: Total COGS | B16: =SUM(B9:B15) -> 6880.43 | C16: =SUM(C9:C15) -> 7165.67 | D16: =SUM(D9:D15) -> 7933.29 | E16: =SUM(E9:E15) -> 10257.96 | F16: =SUM(F9:F15) -> 10396.31 | G16: =G6-G18 -> 11576.282 | H16: =H6-H18 -> 13958.295 | I16: =I6-I18 -> 15644.264 | J16: =J6-J18 -> 17537.793 | K16: =K6-K18 -> 19664.753
A18: Gross Profit | B18: =B4-B16 -> 6180.47 | C18: =C4-C16 -> 8731.04 | D18: =D4-D16 -> 11214.01 | E18: =E4-E16 -> 12388.81 | F18: =F4-F16 -> 13849.01 | G18: =G6*G19 -> 13881.304 | H18: =H6*H19 -> 16737.612 | I18: =I6*I19 -> 18759.285 | J18: =J6*J19 -> 21029.845 | K18: =K6*K19 -> 23580.317
B19: =B18/B6 -> 0.47320399 | C19: =C18/C6 -> 0.54923566 | D19: =D18/D6 -> 0.58567056 | E19: =E18/E6 -> 0.54704534 | F19: =F18/F6 -> 0.57120343 | G19: =AVERAGE(B19:F19) -> 0.5452718 | H19: =G19 -> 0.5452718 | I19: =H19 -> 0.5452718 | J19: =I19 -> 0.5452718 | K19: =J19 -> 0.5452718
A21: OPEX
A22: ATM Cash shortage and claims | F22: 209.72 | G22: 0 | H22: 0 | I22: 0 | J22: 0 | K22: 0
A23: ATM Cash shortage and claims provision | B23: - | C23: - | D23: - | E23: - | F23: 314.07 | G23: 0 | H23: 0 | I23: 0 | J23: 0 | K23: 0
A24: Changes in inventories of finished goods | B24: -273.06 | C24: 177.1 | D24: 29.67 | E24: -567.04 | F24: 435.76 | G24: =F24/F$54*G$54 -> 411.49207 | H24: =G24/G$54*H$54 -> 496.1634 | I24: =H24/H$54*I$54 -> 556.0931 | J24: =I24/I$54*J$54 -> 623.40072 | K24: =J24/J$54*K$54 -> 699.00592
A25: Consumption of stores and spares | B25: 224.04 | C25: 269.92 | D25: 453 | E25: 882.67 | F25: 707.95 | G25: =F25/F$54*G$54 -> 668.52353 | H25: =G25/G$54*H$54 -> 806.08334 | I25: =H25/H$54*I$54 -> 903.44711 | J25: =I25/I$54*J$54 -> 1012.7973 | K25: =J25/J$54*K$54 -> 1135.628
A26: Annual maintenance charges | B26: 225.87 | C26: 341.44 | D26: 457.28 | E26: 442.61 | F26: 450.98 | G26: =F26/F$54*G$54 -> 425.86446 | H26: =G26/G$54*H$54 -> 513.49314 | I26: =H26/H$54*I$54 -> 575.51604 | J26: =I26/I$54*J$54 -> 645.17453 | K26: =J26/J$54*K$54 -> 723.42044
A27: Legal, professional and consultancy fees | B27: 157.84 | C27: 238.03 | D27: 353.61 | E27: 430.85 | F27: 486.38 | G27: =F27/F$54*G$54 -> 459.29299 | H27: =G27/G$54*H$54 -> 553.80015 | I27: =H27/H$54*I$54 -> 620.69158 | J27: =I27/I$54*J$54 -> 695.81797 | K27: =J27/J$54*K$54 -> 780.20585
A28: Courier , freight and forwarding charges | B28: 137.12 | C28: 134.31 | D28: 188.55 | E28: 220.6 | F28: 267.37 | G28: =F28/F$54*G$54 -> 252.47989 | H28: =G28/G$54*H$54 -> 304.43182 | I28: =H28/H$54*I$54 -> 341.20299 | J28: =I28/I$54*J$54 -> 382.50103 | K28: =J28/J$54*K$54 -> 428.89024
A29: Insurance | B29: 169.45 | C29: 173.61 | D29: 226.23 | E29: 234.33 | F29: 274.36 | G29: =F29/F$54*G$54 -> 259.08061 | H29: =G29/G$54*H$54 -> 312.39074 | I29: =H29/H$54*I$54 -> 350.12324 | J29: =I29/I$54*J$54 -> 392.50096 | K29: =J29/J$54*K$54 -> 440.10296
A30: Communication costs | B30: 33.79 | C30: 55.95 | D30: 154.45 | E30: 164.26 | F30: 199.79 | G30: =F30/F$54*G$54 -> 188.66349 | H30: =G30/G$54*H$54 -> 227.48413 | I30: =H30/H$54*I$54 -> 254.96108 | J30: =I30/I$54*J$54 -> 285.8207 | K30: =J30/J$54*K$54 -> 320.48465
A31: Trade receivables written off | B31: 100.84 | C31: 451.28 | D31: - | E31: 912.53 | F31: 259.42 | G31: =F31/F$54*G$54 -> 244.97263 | H31: =G31/G$54*H$54 -> 295.37982 | I31: =H31/H$54*I$54 -> 331.05763 | J31: =I31/I$54*J$54 -> 371.12772 | K31: =J31/J$54*K$54 -> 416.13759
A32: Less : Out of the provision of earlier years | B32: -39.89 | C32: -246.87 | D32: - | E32: -316.49 | F32: -78.47 | G32: =F32/F$54*G$54 -> -74.099924 | H32: =G32/G$54*H$54 -> -89.347214 | I32: =H32/H$54*I$54 -> -100.13913 | J32: =I32/I$54*J$54 -> -112.25962 | K32: =J32/J$54*K$54 -> -125.87432
A33: Impairment allowance for bad and doubtful receivables and deposits | B33: 146 | C33: 595.13 | D33: 984.91 | E33: 310.9 | F33: 185.34 | G33: =F33/F$54*G$54 -> 175.01822 | H33: =G33/G$54*H$54 -> 211.03113 | I33: =H33/H$54*I$54 -> 236.52078 | J33: =I33/I$54*J$54 -> 265.14845 | K33: =J33/J$54*K$54 -> 297.3053
A34: Insurance Claims recievables written off | B34: 12.68 | C34: 38.07 | D34: 29.1 | E34: 16.51 | F34: 7.32 | G34: =F34/F$54*G$54 -> 6.9123416 | H34: =G34/G$54*H$54 -> 8.3346706 | I34: =H34/H$54*I$54 -> 9.3413841 | J34: =I34/I$54*J$54 -> 10.472033 | K34: =J34/J$54*K$54 -> 11.742068
A35: Less : Out of the provision of earlier years | B35: -11.89 | C35: -24.11 | D35: -17.23 | E35: - | F35: - | G35: 0 | H35: 0 | I35: 0 | J35: 0 | K35: 0
A36: Impairment allowance for doubtful insurance claims | B36: - | C36: 7.78 | D36: 3.7 | E36: - | F36: 35 | G36: =F36/F$54*G$54 -> 33.050814 | H36: =G36/G$54*H$54 -> 39.851567 | I36: =H36/H$54*I$54 -> 44.665088 | J36: =I36/I$54*J$54 -> 50.071198 | K36: =J36/J$54*K$54 -> 56.143765
A37: Advances and other Debit balance written off | B37: 1.08 | C37: 21.46 | D37: - | E37: - | F37: - | G37: 0 | H37: 0 | I37: 0 | J37: 0 | K37: 0
A38: Less : Out of the provision of earlier years | B38: - | C38: - | D38: - | E38: - | F38: - | G38: 0 | H38: 0 | I38: 0 | J38: 0 | K38: 0
A39: Repairs and maintenance- Building | B39: 0.1 | C39: 0.11 | D39: 0.63 | E39: - | F39: - | G39: 0 | H39: 0 | I39: 0 | J39: 0 | K39: 0
A40: Repairs and maintenance- Plant and Machinery | B40: 0.35 | C40: 0.1 | D40: 0.19 | E40: - | F40: - | G40: 0 | H40: 0 | I40: 0 | J40: 0 | K40: 0
A41: Repairs and maintenance- Others | B41: 16.34 | C41: 32.31 | D41: 67.3 | E41: 75.21 | F41: 89.01 | G41: =F41/F$54*G$54 -> 84.052941 | H41: =G41/G$54*H$54 -> 101.34823 | I41: =H41/H$54*I$54 -> 113.5897 | J41: =I41/I$54*J$54 -> 127.33821 | K41: =J41/J$54*K$54 -> 142.78162
A42: Payment to auditors | B42: - | C42: - | D42: - | E42: - | F42: - | G42: 0 | H42: 0 | I42: 0 | J42: 0 | K42: 0
A43: As auditors: | B43: - | C43: - | D43: - | E43: - | F43: - | G43: 0 | H43: 0 | I43: 0 | J43: 0 | K43: 0
A44: Audit fees | B44: 6 | C44: 9.97 | D44: 12.03 | E44: 12.72 | F44: 13.82 | G44: =F44/F$54*G$54 -> 13.05035 | H44: =G44/G$54*H$54 -> 15.735676 | I44: =H44/H$54*I$54 -> 17.636329 | J44: =I44/I$54*J$54 -> 19.77097 | K44: =J44/J$54*K$54 -> 22.168767
A45: Reimbursement of expenses | B45: 0.18 | C45: 0.03 | D45: 0.96 | E45: 1 | F45: 0.9 | G45: =F45/F$54*G$54 -> 0.84987807 | H45: =G45/G$54*H$54 -> 1.0247546 | I45: =H45/H$54*I$54 -> 1.1485308 | J45: =I45/I$54*J$54 -> 1.2875451 | K45: =J45/J$54*K$54 -> 1.4436968
...

Sheet Cash Flows
A2: Particulars | B2: 2021 | C2: =B2+1 -> 2022 | D2: =C2+1 -> 2023 | E2: =D2+1 -> 2024 | F2: =E2+1 -> 2025 | G2: =F2+1 -> 2026 | H2: =G2+1 -> 2027 | I2: =H2+1 -> 2028 | J2: =I2+1 -> 2029 | K2: =J2+1 -> 2030
A3: Cash flow from operating activities
A4: Profit before tax | B4: 2377.5 | C4: 3014.45 | D4: 4010.17 | E4: 4670.59 | F4: 4978.39 | G4: ='Income Statement '!G66 -> 4357.6101 | H4: ='Income Statement '!H66 -> 5448.7965 | I4: ='Income Statement '!I66 -> 6142.7469 | J4: ='Income Statement '!J66 -> 6936.6921 | K4: ='Income Statement '!K66 -> 7826.1576
A6: Adjustments to reconcile profit before tax to net cash flow:
A7: Depreciation and amortisation on PP&E and Intangible asset | B7: 412.97 | C7: 580.55 | D7: 899.07 | E7: 1070 | F7: 1150.5 | G7: =Notes!G33+Notes!G13 -> 1124.3993 | H7: =Notes!H33+Notes!H13 -> 1258.0599 | I7: =Notes!I33+Notes!I13 -> 1400.6563 | J7: =Notes!J33+Notes!J13 -> 1561.5703 | K7: =Notes!K33+Notes!K13 -> 1743.1498
A8: Depreciation on Right-of-use assets | B8: 221.58 | C8: 337.88 | D8: 419.11 | E8: 432.16 | F8: 463.82 | G8: =Notes!G53 -> 554.40714 | H8: =Notes!H53 -> 596.34444 | I8: =Notes!I53 -> 645.64866 | J8: =Notes!J53 -> 693.50254 | K8: =Notes!K53 -> 744.56744
A9: Unrealised foreign exchange (gain) / loss | B9: -3.32 | C9: -1.04 | D9: -0.78 | E9: -0.21 | F9: -0.68 | G9: - | H9: - | I9: - | J9: - | K9: -
A10: Lease rent concession | B10: -20.07 | C10: -1.73 | G10: - | H10: - | I10: - | J10: - | K10: -
A11: Impairment allowance for bad and receivables and deposits | B11: 206 | C11: 595.13 | D11: 984.91 | E11: 906.94 | F11: 366.3 | G11: =SUM('Income Statement '!G31:G33) -> 345.89093 | H11: =SUM('Income Statement '!H31:H33) -> 417.06373 | I11: =SUM('Income Statement '!I31:I33) -> 467.43929 | J11: =SUM('Income Statement '!J31:J33) -> 524.01654 | K11: =SUM('Income Statement '!K31:K33) -> 587.56857
A12: ATM Cash shortage and claims provision | B12: - | C12: - | D12: - | E12: - | F12: 523.79 | G12: ='Income Statement '!G22+'Income Statement '!G23 -> 0 | H12: ='Income Statement '!H22+'Income Statement '!H23 -> 0 | I12: ='Income Statement '!I22+'Income Statement '!I23 -> 0 | J12: ='Income Statement '!J22+'Income Statement '!J23 -> 0 | K12: ='Income Statement '!K22+'Income Statement '!K23 -> 0
A13: Bad debts written off | B13: 222.78 | C13: 204.41 | D13: - | E13: - | F13: - | G13: - | H13: - | I13: - | J13: - | K13: -
A14: Debit balance written off | B14: 1.08 | C14: 21.46 | D14: - | E14: - | F14: - | G14: ='Income Statement '!G37 -> 0 | H14: ='Income Statement '!H37 -> 0 | I14: ='Income Statement '!I37 -> 0 | J14: ='Income Statement '!J37 -> 0 | K14: ='Income Statement '!K37 -> 0
A15: (Profit) on disposal of PP&E (net) | B15: -1.4 | C15: -5.38 | D15: -11.31 | E15: -11.85 | F15: -23.67 | G15: =-'Income Statement '!G72 -> -7.9927968 | H15: =-'Income Statement '!H72 -> -2.7545447 | I15: =-'Income Statement '!I72 -> 0 | J15: =-'Income Statement '!J72 -> 0 | K15: =-'Income Statement '!K72 -> 0
A16: Sundry balances written back | B16: -52.76 | C16: -7.8 | D16: -20.11 | E16: -21.97 | F16: -29.77 | G16: =-'Income Statement '!G69 -> -134.45185 | H16: =-'Income Statement '!H69 -> -95.010273 | I16: =-'Income Statement '!I69 -> -27.971793 | J16: =-'Income Statement '!J69 -> -11.826373 | K16: =-'Income Statement '!K69 -> -3.7725227
A17: Impairment for doubtful claims receivables | B17: - | C17: 7.78 | D17: 3.7 | E17: - | F17: 35 | G17: ='Income Statement '!G36 -> 33.050814 | H17: ='Income Statement '!H36 -> 39.851567 | I17: ='Income Statement '!I36 -> 44.665088 | J17: ='Income Statement '!J36 -> 50.071198 | K17: ='Income Statement '!K36 -> 56.143765
A18: Insurance claims recievables written off | B18: 0.79 | C18: 13.96 | D18: 11.87 | E18: 16.51 | F18: 7.32 | G18: ='Income Statement '!G34 -> 6.9123416 | H18: ='Income Statement '!H34 -> 8.3346706 | I18: ='Income Statement '!I34 -> 9.3413841 | J18: ='Income Statement '!J34 -> 10.472033 | K18: ='Income Statement '!K34 -> 11.742068
A19: Net gain on lease modification | D19: -3.47 | E19: -9.89 | F19: -8.97 | G19: =-'Income Statement '!G73 -> -2.2811104 | H19: =-'Income Statement '!H73 -> 0 | I19: =-'Income Statement '!I73 -> 0 | J19: =-'Income Statement '!J73 -> 0 | K19: =-'Income Statement '!K73 -> 0
A20: Finance income | B20: -53.06 | C20: -33.13 | D20: -69.59 | E20: -136.59 | F20: -202.66 | G20: ='Income Statement '!G62 -> -100 | H20: ='Income Statement '!H62 -> -100 | I20: ='Income Statement '!I62 -> -100 | J20: ='Income Statement '!J62 -> -100 | K20: ='Income Statement '!K62 -> -100
A21: Profit on sale of current investments | B21: -7.65 | C21: -20.58 | D21: -29.52 | E21: -92.34 | F21: -150.89 | G21: =-'Income Statement '!G70 -> -78.680486 | H21: =-'Income Statement '!H70 -> -25.468779 | I21: =-'Income Statement '!I70 -> -10.600211 | J21: =-'Income Statement '!J70 -> -3.3751968 | K21: =-'Income Statement '!K70 -> 0
A22: Net change in FV of current investments measured at FVTPL | B22: -3.91 | C22: -4.12 | D22: -12.42 | E22: -63.89 | F22: -88.3 | G22: =-'Income Statement '!G71 -> -21.09136 | H22: =-'Income Statement '!H71 -> -9.6516665 | I22: =-'Income Statement '!I71 -> -3.0252552 | J22: =-'Income Statement '!J71 -> 0 | K22: =-'Income Statement '!K71 -> 0
A23: Employee stock option compensation cost | B23: 19.61 | C23: 61.19 | D23: 92.8 | E23: 365.55 | F23: 307.45 | G23: =0.23*'Income Statement '!G50 -> 748.28836 | H23: =0.23*'Income Statement '!H50 -> 902.26112 | I23: =0.23*'Income Statement '!I50 -> 1011.2418 | J23: =0.23*'Income Statement '!J50 -> 1133.6391 | K23: =0.23*'Income Statement '!K50 -> 1271.1253
A24: Finance costs | B24: 82.32 | C24: 143.9 | D24: 196.15 | E24: 162.1 | F24: 181.97 | G24: ='Income Statement '!G63 -> 173.40405 | H24: ='Income Statement '!H63 -> 163.8168 | I24: ='Income Statement '!I63 -> 167.80016 | J24: ='Income Statement '!J63 -> 164.46819 | K24: ='Income Statement '!K63 -> 164.94183
A25: Operating profit before working capital changes | B25: =SUM(B4:B24) -> 3402.46 | C25: =SUM(C4:C24) -> 4906.93 | D25: =SUM(D4:D24) -> 6470.58 | E25: =SUM(E4:E24) -> 7287.11 | F25: =SUM(F4:F24) -> 7509.6 | G25: =SUM(G4:G24) -> 6999.4655 | H25: =SUM(H4:H24) -> 8601.6435 | I25: =SUM(I4:I24) -> 9747.9423 | ... K25: =SUM(K4:K24) -> 12301.624
A27: Movement in working capital :
A28: (Decrease) / Increase in trade payables and other liabilities | B28: 282.54 | C28: -421.03 | D28: -824.02 | E28: 1991.4 | F28: -391.05 | G28: =('Balance Sheet'!H50+'Balance Sheet'!H51)-('Balance Sheet'!G50+'Balance Sheet'!G51) -> 619.95205 | H28: =('Balance Sheet'!I50+'Balance Sheet'!I51)-('Balance Sheet'!H50+'Balance Sheet'!H51) -> 1198.8893 | I28: =('Balance Sheet'!J50+'Balance Sheet'!J51)-('Balance Sheet'!I50+'Balance Sheet'!I51) -> -354.53554 | J28: =('Balance Sheet'!K50+'Balance Sheet'!K51)-('Balance Sheet'!J50+'Balance Sheet'!J51) -> 1705.0653 | K28: =('Balance Sheet'!L50+'Balance Sheet'!L51)-('Balance Sheet'!K50+'Balance Sheet'!K51) -> 31.21542
A29: Increase in provisions | B29: 0.35 | C29: 21.37 | D29: 11.59 | E29: 15.37 | F29: -87.46 | G29: =('Balance Sheet'!G43-'Balance Sheet'!H43)+('Balance Sheet'!G53-'Balance Sheet'!H53) -> 5.6843419e-14 | H29: =('Balance Sheet'!H43-'Balance Sheet'!I43)+('Balance Sheet'!H53-'Balance Sheet'!I53) -> 0 | I29: =('Balance Sheet'!I43-'Balance Sheet'!J43)+('Balance Sheet'!I53-'Balance Sheet'!J53) -> 0 | J29: =('Balance Sheet'!J43-'Balance Sheet'!K43)+('Balance Sheet'!J53-'Balance Sheet'!K53) -> 0 | K29: =('Balance Sheet'!K43-'Balance Sheet'!L43)+('Balance Sheet'!K53-'Balance Sheet'!L53) -> 0
A30: Decrease / (Increase) in inventories | B30: -464.29 | C30: 265.45 | D30: -106.87 | E30: -526.9 | F30: 472.77 | G30: ='Balance Sheet'!G20-'Balance Sheet'!H20 -> 124.74568 | H30: ='Balance Sheet'!H20-'Balance Sheet'!I20 -> -426.58765 | I30: ='Balance Sheet'!I20-'Balance Sheet'!J20 -> 212.94625 | J30: ='Balance Sheet'!J20-'Balance Sheet'!K20 -> -452.88889 | K30: ='Balance Sheet'!K20-'Balance Sheet'!L20 -> 183.36643
A31: (Increase) in trade receivables | B31: -949.82 | C31: -724.27 | D31: -1251.74 | E31: -2844.04 | F31: -1314.7 | G31: ='Balance Sheet'!G23-'Balance Sheet'!H23 -> 2374.9521 | H31: ='Balance Sheet'!H23-'Balance Sheet'!I23 -> -5295.2961 | I31: ='Balance Sheet'!I23-'Balance Sheet'!J23 -> 3278.554 | J31: ='Balance Sheet'!J23-'Balance Sheet'!K23 -> -5543.8585 | K31: ='Balance Sheet'!K23-'Balance Sheet'!L23 -> 2998.9844
A32: (Increase) / Decrease in other assets and prepayments | B32: 152.34 | C32: -507.51 | D32: 853.07 | E32: -296.45 | F32: -234.84 | G32: =('Balance Sheet'!G17-'Balance Sheet'!H17)+('Balance Sheet'!G28-'Balance Sheet'!H28) -> 0 | H32: =('Balance Sheet'!H17-'Balance Sheet'!I17)+('Balance Sheet'!H28-'Balance Sheet'!I28) -> 0 | I32: =('Balance Sheet'!I17-'Balance Sheet'!J17)+('Balance Sheet'!I28-'Balance Sheet'!J28) -> 0 | J32: =('Balance Sheet'!J17-'Balance Sheet'!K17)+('Balance Sheet'!J28-'Balance Sheet'!K28) -> 0 | K32: =('Balance Sheet'!K17-'Balance Sheet'!L17)+('Balance Sheet'!K28-'Balance Sheet'!L28) -> 0
A33: CFO Before Tax | B33: =B25+SUM(B28:B32) -> 2423.58 | C33: =C25+SUM(C28:C32) -> 3540.94 | D33: =D25+SUM(D28:D32) -> 5152.61 | E33: =E25+SUM(E28:E32) -> 5626.49 | F33: =F25+SUM(F28:F32) -> 5954.32 | G33: =G25+SUM(G28:G32) -> 10119.115 | H33: =H25+SUM(H28:H32) -> 4078.649 | I33: =I25+SUM(I28:I32) -> 12884.907 | ... K33: =K25+SUM(K28:K32) -> 15515.19
A35: Direct taxes paid (net of refunds) | B35: -569.16 | C35: -975.82 | D35: -1084.98 | E35: -1227.57 | F35: -1129.04 | G35: =-'Income Statement '!G83 -> -1115.8554 | H35: =-'Income Statement '!H83 -> -1359.8391 | I35: =-'Income Statement '!I83 -> -1507.347 | J35: =-'Income Statement '!J83 -> -1698.8 | K35: =-'Income Statement '!K83 -> -1918.7475
A36: Net cash flow generated from operating activities (A) | B36: =B33+B35 -> 1854.42 | C36: =C33+C35 -> 2565.12 | D36: =D33+D35 -> 4067.63 | E36: =E33+E35 -> 4398.92 | F36: =F33+F35 -> 4825.28 | G36: =G33+G35 -> 9003.2599 | H36: =H33+H35 -> 2718.8099 | I36: =I33+I35 -> 11377.56 | ... K36: =K33+K35 -> 13596.443
C37: =C36/B36-1 -> 0.38324651 | D37: =D36/C36-1 -> 0.58574648 | E37: =E36/D36-1 -> 0.081445461 | F37: =F36/E36-1 -> 0.09692379
A38: Cash flows from investing activities
A39: Proceeds from sale of property, plant and equipment | B39: 49.09 | C39: 7.04 | D39: 19.57 | E39: 22.86 | F39: 24.37 | G39: ='Income Statement '!G72 -> 7.9927968 | H39: ='Income Statement '!H72 -> 2.7545447 | I39: ='Income Statement '!I72 -> 0 | J39: ='Income Statement '!J72 -> 0 | K39: ='Income Statement '!K72 -> 0
A40: Purchase of PPE,Intangible assets (including CWIP capital advances) | B40: -550.86 | C40: -2839.67 | D40: -1933.18 | E40: -1083.76 | F40: -1543.37 | G40: =-Notes!G6-1000 -> -2500 | H40: =-Notes!H6-1000 -> -2600 | I40: =-Notes!I6-1000 -> -2700 | J40: =-Notes!J6-1000 -> -3000 | K40: =-Notes!K6-1000 -> -3100
A41: Investment in mutual funds | B41: -3356.82 | C41: -8304.68 | D41: -11578.43 | E41: -15408.41 | F41: -16461.65 | G41: -500 | H41: =G41-100 -> -600 | I41: =H41-100 -> -700 | J41: =I41-100 -> -800 | K41: =J41-100 -> -900
A42: Proceeds from redemption of mutual funds | B42: 2812.05 | C42: 8217.41 | D42: 10399.99 | E42: 13505.63 | F42: 15389.14 | G42: 0 | H42: 0 | I42: 0 | J42: 0 | K42: 0
A43: Loan given to Others | B43: - | C43: -143.86 | G43: 0 | H43: 0 | I43: 0 | J43: 0 | K43: 0
A44: Investment in deposits with banks | B44: -2521.9 | C44: -844.53 | D44: -1071.42 | E44: -1568.47 | F44: -648.76 | G44: 0 | H44: 0 | I44: 0 | J44: 0 | K44: 0
...

Sheet Notes
A1: Particulars | B1: 2021 | C1: =B1+1 -> 2022 | D1: =C1+1 -> 2023 | E1: =D1+1 -> 2024 | F1: =E1+1 -> 2025 | G1: =F1+1 -> 2026 | H1: =G1+1 -> 2027 | I1: =H1+1 -> 2028 | J1: =I1+1 -> 2029 | K1: =J1+1 -> 2030
A2: PP&E | M2: Receivables
A3: Gross Carrying Amount | N3: 2023 | O3: 2024 | P3: 2025 | Q3: =P3+1 -> 2026 | R3: =Q3+1 -> 2027 | S3: =R3+1 -> 2028 | T3: =S3+1 -> 2029 | U3: =T3+1 -> 2030
M4: Balance | O4: 1328.33 | P4: =O8 -> 1322.74 | Q4: =P8 -> 766.81 | R4: =Q8 -> 867.7283 | S4: =R8 -> 989.41221 | T4: =S8 -> 1125.7939 | U4: =T8 -> 1278.6827
A5: Opening | B5: 3609.4 | C5: =B8 -> 4468.32 | D5: =C8 -> 6428.77 | E5: =D8 -> 8166.33 | F5: =E8 -> 8781.59 | G5: =F8 -> 9767.73 | H5: =G8 -> 10995.394 | I5: =H8 -> 12310.237 | J5: =I8 -> 13703.788 | K5: =J8 -> 15398.954 | M5: transfer | P5: -662.8 | Q5: 0 | R5: 0 | S5: 0 | T5: 0 | U5: 0
A6: Additions | B6: 1067.15 | C6: =182.5+1956.65 -> 2139.15 | D6: 2052.08 | E6: 987.44 | F6: 1274.19 | G6: 1500 | H6: 1600 | I6: 1700 | J6: 2000 | K6: 2100 | M6: Write back | N6: ='Income Statement '!D32 -> - | O6: ='Income Statement '!E32 -> -316.49 | P6: ='Income Statement '!F32 -> -78.47 | Q6: ='Income Statement '!G32 -> -74.099924 | R6: ='Income Statement '!H32 -> -89.347214 | S6: ='Income Statement '!I32 -> -100.13913 | T6: ='Income Statement '!J32 -> -112.25962 | U6: ='Income Statement '!K32 -> -125.87432
A7: Deletions | B7: 208.23 | C7: 178.7 | D7: 314.52 | E7: 372.18 | F7: 288.05 | G7: =AVERAGE(B7:F7) -> 272.336 | H7: =AVERAGE(C7:G7) -> 285.1572 | I7: =AVERAGE(D7:H7) -> 306.44864 | J7: =AVERAGE(E7:I7) -> 304.83437 | K7: =AVERAGE(F7:J7) -> 291.36524 | M7: Remeasure | N7: ='Income Statement '!D33 -> 984.91 | O7: ='Income Statement '!E33 -> 310.9 | P7: ='Income Statement '!F33 -> 185.34 | Q7: ='Income Statement '!G33 -> 175.01822 | R7: ='Income Statement '!H33 -> 211.03113 | S7: ='Income Statement '!I33 -> 236.52078 | T7: ='Income Statement '!J33 -> 265.14845 | U7: ='Income Statement '!K33 -> 297.3053
A8: Closing | B8: =B5+B6-B7 -> 4468.32 | C8: =C5+C6-C7 -> 6428.77 | D8: =D5+D6-D7 -> 8166.33 | E8: =E5+E6-E7 -> 8781.59 | F8: =F5+F6-F7 -> 9767.73 | G8: =G5+G6-G7 -> 10995.394 | H8: =H5+H6-H7 -> 12310.237 | I8: =I5+I6-I7 -> 13703.788 | ... K8: =K5+K6-K7 -> 17207.589 | N8: =SUM(N4:N7) -> 984.91 | O8: =SUM(O4:O7) -> 1322.74 | P8: =SUM(P4:P7) -> 766.81 | Q8: =SUM(Q4:Q7) -> 867.7283 | R8: =SUM(R4:R7) -> 989.41221 | S8: =SUM(S4:S7) -> 1125.7939 | T8: =SUM(T4:T7) -> 1278.6827 | U8: =SUM(U4:U7) -> 1450.1137
A10: Depriciation
A12: Opening | B12: 2403.27 | C12: =B15 -> 2571.32 | D12: =C15 -> 2959.05 | E12: =D15 -> 3469.38 | F12: =E15 -> 4104.55 | G12: =F15 -> 4925.33 | H12: =G15 -> 5744.9433 | I12: =H15 -> 6675.9324 | J12: =I15 -> 7726.6021 | K12: =J15 -> 8937.0869
A13: Depriciation | B13: 328.58 | C13: =497.69 +67 -> 564.69 | D13: =807.2+9.39 -> 816.59 | E13: 996.34 | F13: 1108.13 | G13: =G19*G20 -> 1078.0673 | H13: =H19*H20 -> 1209.0279 | I13: =I19*I20 -> 1348.9243 | J13: =J19*J20 -> 1507.1383 | K13: =K19*K20 -> 1686.0178
A14: Deletion | B14: 160.53 | C14: 176.96 | D14: 306.26 | E14: 361.17 | F14: 287.35 | G14: =AVERAGE(B14:F14) -> 258.454 | H14: =AVERAGE(C14:G14) -> 278.0388 | I14: =AVERAGE(D14:H14) -> 298.25456 | J14: =AVERAGE(E14:I14) -> 296.65347 | K14: =AVERAGE(F14:J14) -> 283.75017
A15: Closing | B15: =B12+B13-B14 -> 2571.32 | C15: =C12+C13-C14 -> 2959.05 | D15: =D12+D13-D14 -> 3469.38 | E15: =E12+E13-E14 -> 4104.55 | F15: =F12+F13-F14 -> 4925.33 | G15: =G12+G13-G14 -> 5744.9433 | H15: =H12+H13-H14 -> 6675.9324 | I15: =I12+I13-I14 -> 7726.6021 | ... K15: =K12+K13-K14 -> 10339.355
A17: Net Carrying Value | B17: =B8-B15 -> 1897 | C17: =C8-C15 -> 3469.72 | D17: =D8-D15 -> 4696.95 | E17: =E8-E15 -> 4677.04 | F17: =F8-F15 -> 4842.4 | G17: =G8-G15 -> 5250.4507 | H17: =H8-H15 -> 5634.3044 | I17: =I8-I15 -> 5977.186 | ... K17: =K8-K15 -> 6868.234
A19: PP&E | B19: =B5+(B6/2) -> 4142.975 | C19: =C5+(C6/2) -> 5537.895 | D19: =D5+(D6/2) -> 7454.81 | E19: =E5+(E6/2) -> 8660.05 | F19: =F5+(F6/2) -> 9418.685 | G19: =G5+(G6/2) -> 10517.73 | H19: =H5+(H6/2) -> 11795.394 | I19: =I5+(I6/2) -> 13160.237 | ... K19: =K5+(K6/2) -> 16448.954
A20: Depri% | B20: =B13/B19 -> 0.079310158 | C20: =C13/C19 -> 0.10196835 | D20: =D13/D19 -> 0.10953867 | E20: =E13/E19 -> 0.11505014 | F20: =F13/F19 -> 0.1176523 | G20: 0.1025 | H20: 0.1025 | I20: 0.1025 | J20: 0.1025 | K20: 0.1025
A22: INTANGIBLE ASSETS
A23: Gross Carrying Amount
A25: Opening | B25: 508.37 | C25: =B28 -> 598.94 | D25: =C28 -> 668.76 | E25: =D28 -> 696.37 | F25: =E28 -> 724.32 | G25: =F28 -> 749.7 | H25: =G28 -> 794.7 | I25: =H28 -> 839.7 | J25: =I28 -> 884.7 | K25: =J28 -> 929.7
A26: Additions | B26: 90.57 | C26: =21.72+48.1 -> 69.82 | D26: 27.93 | E26: 27.99 | F26: 25.38 | G26: 45 | H26: 45 | I26: 45 | J26: 45 | K26: 45
A27: Deletions | B27: 0 | C27: 0 | D27: 0.32 | E27: 0.04 | F27: 0 | G27: 0 | H27: 0 | I27: 0 | J27: 0 | K27: 0
A28: Closing | B28: =B25+B26-B27 -> 598.94 | C28: =C25+C26-C27 -> 668.76 | D28: =D25+D26-D27 -> 696.37 | E28: =E25+E26-E27 -> 724.32 | F28: =F25+F26-F27 -> 749.7 | G28: =G25+G26-G27 -> 794.7 | H28: =H25+H26-H27 -> 839.7 | I28: =I25+I26-I27 -> 884.7 | ... K28: =K25+K26-K27 -> 974.7
A30: Amortization
A32: Opening | B32: 325.01 | C32: =B35 -> 409.4 | D32: =C35 -> 495.68 | E32: =D35 -> 587.23 | F32: =E35 -> 660.93 | G32: =F35 -> 703.3 | H32: =G35 -> 749.632 | I32: =H35 -> 798.664 | J32: =I35 -> 850.396 | K32: =J35 -> 904.828
A33: Amortization | B33: 84.39 | C33: =82.88+3.4 -> 86.28 | D33: 91.87 | E33: 73.74 | F33: 42.37 | G33: =G39*G40 -> 46.332 | H33: =H39*H40 -> 49.032 | I33: =I39*I40 -> 51.732 | J33: =J39*J40 -> 54.432 | K33: =K39*K40 -> 57.132
A34: Deletion | B34: 0 | D34: 0.32 | E34: 0.04 | F34: 0 | G34: 0 | H34: 0 | I34: 0 | J34: 0 | K34: 0
A35: Closing | B35: =B32+B33-B34 -> 409.4 | C35: =C32+C33-C34 -> 495.68 | D35: =D32+D33-D34 -> 587.23 | E35: =E32+E33-E34 -> 660.93 | F35: =F32+F33-F34 -> 703.3 | G35: =G32+G33-G34 -> 749.632 | H35: =H32+H33-H34 -> 798.664 | I35: =I32+I33-I34 -> 850.396 | ... K35: =K32+K33-K34 -> 961.96
A37: Net Carrying Value | B37: =B28-B35 -> 189.54 | C37: =C28-C35 -> 173.08 | D37: =D28-D35 -> 109.14 | E37: =E28-E35 -> 63.39 | F37: =F28-F35 -> 46.4 | G37: =G28-G35 -> 45.068 | H37: =H28-H35 -> 41.036 | I37: =I28-I35 -> 34.304 | ... K37: =K28-K35 -> 12.74
B39: =B25+(B26/2) -> 553.655 | C39: =C25+(C26/2) -> 633.85 | D39: =D25+(D26/2) -> 682.725 | E39: =E25+(E26/2) -> 710.365 | F39: =F25+(F26/2) -> 737.01 | G39: =G25+(G26/2) -> 772.2 | H39: =H25+(H26/2) -> 817.2 | I39: =I25+(I26/2) -> 862.2 | ... K39: =K25+(K26/2) -> 952.2
A40: Amortization | B40: =B33/B39 -> 0.15242344 | C40: =C33/C39 -> 0.13612053 | D40: =D33/D39 -> 0.1345637 | E40: =E33/E39 -> 0.10380579 | F40: =F33/F39 -> 0.057489044 | G40: 0.06 | H40: 0.06 | I40: 0.06 | J40: 0.06 | K40: 0.06
A42: Right-Of-Use Assets
A43: Gross Carrying Amount
A45: Opening | B45: 1047.02 | C45: =B48 -> 1589.28 | D45: =C48 -> 2357.82 | E45: =D48 -> 2750.02 | F45: =E48 -> 2811.22 | G45: =F48 -> 3149.84 | H45: =G48 -> 3569.694 | I45: =H48 -> 3967.1468 | J45: =I48 -> 4366.1482 | K45: =J48 -> 4759.5838
A46: Additions | B46: 760.4 | C46: 978.83 | D46: 565.37 | E46: 231.54 | F46: 592.41 | G46: 625 | H46: 600 | I46: 600 | J46: 600 | K46: 600
A47: Deletions | B47: 218.14 | C47: 210.29 | D47: 173.17 | E47: 170.34 | F47: 253.79 | G47: =AVERAGE(B47:F47) -> 205.146 | H47: =AVERAGE(C47:G47) -> 202.5472 | I47: =AVERAGE(D47:H47) -> 200.99864 | J47: =AVERAGE(E47:I47) -> 206.56437 | K47: =AVERAGE(F47:J47) -> 213.80924
A48: Closing | B48: =B45+B46-B47 -> 1589.28 | C48: =C45+C46-C47 -> 2357.82 | D48: =D45+D46-D47 -> 2750.02 | E48: =E45+E46-E47 -> 2811.22 | F48: =F45+F46-F47 -> 3149.84 | G48: =G45+G46-G47 -> 3569.694 | H48: =H45+H46-H47 -> 3967.1468 | I48: =I45+I46-I47 -> 4366.1482 | ... K48: =K45+K46-K47 -> 5145.7746
A50: Depriciation
A52: Opening | B52: 208.43 | C52: =B55 -> 378.49 | D52: =C55 -> 557.83 | E52: =D55 -> 923.55 | F52: =E55 -> 1253.7 | G52: =F55 -> 1525.9 | H52: =G55 -> 2030.3071 | I52: =H55 -> 2526.6516 | J52: =I55 -> 3072.3002 | K52: =J55 -> 3565.8028
A53: Depriciation | B53: 221.58 | C53: 337.88 | D53: 419.11 | E53: 432.06 | F53: 463.82 | G53: =G60*G48 -> 554.40714 | H53: =H60*H48 -> 596.34444 | I53: =I60*I48 -> 645.64866 | J53: =J60*J48 -> 693.50254 | K53: =K60*K48 -> 744.56744
A54: Deletion | B54: 51.52 | C54: 158.54 | D54: 53.39 | E54: 101.91 | F54: 191.62 | G54: 50 | H54: 100 | I54: 100 | J54: 200 | K54: 300
...

Sheet Ratios
I1: Forecast
B2: Particulars | C2: 2020 | D2: 2021 | E2: =D2+1 -> 2022 | F2: =E2+1 -> 2023 | G2: =F2+1 -> 2024 | H2: =G2+1 -> 2025 | I2: =H2+1 -> 2026 | J2: =I2+1 -> 2027 | K2: =J2+1 -> 2028 | L2: =K2+1 -> 2029 | M2: =L2+1 -> 2030
B4: Activity Ratios
B6: Inventory T/O | D6: ='Income Statement '!B16/Ratios!D8 -> 10.384222 | E6: ='Income Statement '!C16/Ratios!E8 -> 9.4037664 | F6: ='Income Statement '!D16/Ratios!F8 -> 11.573251 | G6: ='Income Statement '!E16/Ratios!G8 -> 10.205402 | H6: ='Income Statement '!F16/Ratios!H8 -> 10.071845 | I6: =365/I7 -> 10.281287 | J6: =365/J7 -> 10.281287 | K6: =365/K7 -> 10.281287 | L6: =365/L7 -> 10.281287 | M6: =365/M7 -> 10.281287
B7: Inventory Days | D7: =365/D6 -> 35.149478 | E7: =365/E6 -> 38.814235 | F7: =365/F6 -> 31.538243 | G7: =365/G6 -> 35.765371 | H7: =365/H6 -> 36.239635 | I7: =AVERAGE(D7:H7) -> 35.501392 | J7: 35.501392 | K7: 35.501392 | L7: 35.501392 | M7: 35.501392
B8: Avg inventory | D8: =(C10+D10)/2 -> 662.585 | E8: =(D10+E10)/2 -> 762 | F8: =(E10+F10)/2 -> 685.485 | G8: =(F10+G10)/2 -> 1005.15 | H8: =(G10+H10)/2 -> 1032.215 | I8: =(H10+I10)/2 -> 733.45716 | J8: =(I10+J10)/2 -> 884.37814 | K8: =(J10+K10)/2 -> 991.19885 | ... M8: =(L10+M10)/2 -> 1245.9314
B10: Inventory | C10: 430.44 | D10: ='Balance Sheet'!C20 -> 894.73 | E10: ='Balance Sheet'!D20 -> 629.27 | F10: ='Balance Sheet'!E20 -> 741.7 | G10: ='Balance Sheet'!F20 -> 1268.6 | H10: ='Balance Sheet'!G20 -> 795.83 | I10: =((('Income Statement '!G9+'Income Statement '!G10)*2)/Ratios!I6)-'Balance Sheet'!G20 -> 671.08432 | J10: =((('Income Statement '!H9+'Income Statement '!H10)*2)/Ratios!J6)-'Balance Sheet'!H20 -> 1097.672 | K10: =((('Income Statement '!I9+'Income Statement '!I10)*2)/Ratios!K6)-'Balance Sheet'!I20 -> 884.72572 | L10: =((('Income Statement '!J9+'Income Statement '!J10)*2)/Ratios!L6)-'Balance Sheet'!J20 -> 1337.6146 | M10: =((('Income Statement '!K9+'Income Statement '!K10)*2)/Ratios!M6)-'Balance Sheet'!K20 -> 1154.2482
B12: Payable Turnover | D12: =(('Income Statement '!B9+'Income Statement '!B10))/Ratios!D15 -> 2.1558603 | E12: =(('Income Statement '!C9+'Income Statement '!C10))/Ratios!E15 -> 1.6227669 | F12: =(('Income Statement '!D9+'Income Statement '!D10))/Ratios!F15 -> 2.0527701 | G12: =(('Income Statement '!E9+'Income Statement '!E10))/Ratios!G15 -> 2.2313337 | H12: =(('Income Statement '!F9+'Income Statement '!F10))/Ratios!H15 -> 1.7985017 | I12: =365/I13 -> 1.9444578 | J12: =365/J13 -> 1.9070568 | K12: =365/K13 -> 1.9763019 | L12: =365/L13 -> 1.9616868 | M12: =365/M13 -> 1.9153935
B13: Payable Days | D13: =365/D12 -> 169.30596 | E13: =365/E12 -> 224.92449 | F13: =365/F12 -> 177.80851 | G13: =365/G12 -> 163.5793 | H13: =365/H12 -> 202.94671 | I13: =AVERAGE(D13:H13) -> 187.71299 | J13: =AVERAGE(E13:I13) -> 191.3944 | K13: =AVERAGE(F13:J13) -> 184.68838 | L13: =AVERAGE(G13:K13) -> 186.06436 | M13: =AVERAGE(H13:L13) -> 190.56137
B14: Payables
B15: Avg payables | D15: =(D17+C17)/2 -> 2431.665 | E15: =(E17+D17)/2 -> 2814.97 | F15: =(F17+E17)/2 -> 2410.265 | G15: =(G17+F17)/2 -> 3141.09 | H15: =(H17+G17)/2 -> 3765.49 | I15: =(Ratios!I17+Ratios!H17)/2 -> 3878.142 | J15: =(Ratios!J17+Ratios!I17)/2 -> 4835.0678 | K15: =(Ratios!K17+Ratios!J17)/2 -> 5204.0046 | L15: =(Ratios!L17+Ratios!K17)/2 -> 5837.6776 | M15: =(Ratios!M17+Ratios!L17)/2 -> 6693.7183
B17: Payables | C17: 1801.78 | D17: ='Balance Sheet'!C50+'Balance Sheet'!C51 -> 3061.55 | E17: ='Balance Sheet'!D50+'Balance Sheet'!D51 -> 2568.39 | F17: ='Balance Sheet'!E50+'Balance Sheet'!E51 -> 2252.14 | G17: ='Balance Sheet'!F50+'Balance Sheet'!F51 -> 4030.04 | H17: ='Balance Sheet'!G50+'Balance Sheet'!G51 -> 3500.94 | I17: =((('Income Statement '!G9+'Income Statement '!G10)*2)/I12)-('Balance Sheet'!G51+'Balance Sheet'!G50) -> 4255.3439 | J17: =((('Income Statement '!H9+'Income Statement '!H10)*2)/J12)-('Balance Sheet'!H51+'Balance Sheet'!H50) -> 5414.7916 | K17: =((('Income Statement '!I9+'Income Statement '!I10)*2)/K12)-('Balance Sheet'!I51+'Balance Sheet'!I50) -> 4993.2176 | L17: =((('Income Statement '!J9+'Income Statement '!J10)*2)/L12)-('Balance Sheet'!J51+'Balance Sheet'!J50) -> 6682.1375 | M17: =((('Income Statement '!K9+'Income Statement '!K10)*2)/M12)-('Balance Sheet'!K51+'Balance Sheet'!K50) -> 6705.2991
B19: Recievable Turnover | D19: ='Income Statement '!B6/D22 -> 3.1277 | E19: ='Income Statement '!C6/E22 -> 3.4270713 | F19: ='Income Statement '!D6/F22 -> 4.0183295 | G19: ='Income Statement '!E6/G22 -> 3.6359443 | H19: ='Income Statement '!F6/H22 -> 3.1605065 | I19: =365/I20 -> 3.4439663 | J19: =365/J20 -> 3.4439663 | K19: =365/K20 -> 3.4439663 | L19: =365/L20 -> 3.4439663 | M19: =365/M20 -> 3.4439663
B20: Recievable Days | D20: =365/D19 -> 116.69917 | E20: =365/E19 -> 106.50493 | F20: =365/F19 -> 90.833765 | G20: =365/G19 -> 100.38658 | H20: =365/H19 -> 115.48782 | I20: =AVERAGE(D20:H20) -> 105.98245 | J20: 105.98245 | K20: 105.98245 | L20: 105.98245 | M20: 105.98245
B21: Recievables
B22: Avg receivables | D22: =(D24+C24)/2 -> 4175.88 | E22: =(E24+D24)/2 -> 4638.57 | F22: =(F24+E24)/2 -> 4764.99 | G22: =(G24+F24)/2 -> 6228.58 | H22: =(H24+G24)/2 -> 7671.34 | I22: =('Income Statement '!G4*2)/Ratios!I19 -> 14783.876 | J22: =('Income Statement '!H4*2)/Ratios!J19 -> 17825.904 | K22: =('Income Statement '!I4*2)/Ratios!K19 -> 19979.028 | L22: =('Income Statement '!J4*2)/Ratios!L19 -> 22397.221 | M22: =('Income Statement '!K4*2)/Ratios!M19 -> 25113.526
B24: Recievable | C24: 3344.57 | D24: ='Balance Sheet'!C23 -> 5007.19 | E24: ='Balance Sheet'!D23 -> 4269.95 | F24: ='Balance Sheet'!E23 -> 5260.03 | G24: ='Balance Sheet'!F23 -> 7197.13 | H24: ='Balance Sheet'!G23 -> 8145.55 | I24: =I22-'Balance Sheet'!G23 -> 6638.3262 | J24: =J22-'Balance Sheet'!H23 -> 12055.306 | K24: =K22-'Balance Sheet'!I23 -> 8913.1339 | L24: =L22-'Balance Sheet'!J23 -> 14609.881 | M24: =M22-'Balance Sheet'!K23 -> 11782.328
B26: Operating Cycle | D26: =D7+D20 -> 151.84865 | E26: =E7+E20 -> 145.31917 | F26: =F7+F20 -> 122.37201 | G26: =G7+G20 -> 136.15195 | H26: =H7+H20 -> 151.72745 | I26: =I7+I20 -> 141.48385 | J26: =J7+J20 -> 141.48385 | K26: =K7+K20 -> 141.48385 | ... M26: =M7+M20 -> 141.48385
B27: Cash Conversion Cycle | D27: =D20+D7-D13 -> -17.457313 | E27: =E20+E7-E13 -> -79.605317 | F27: =F20+F7-F13 -> -55.436503 | G27: =G20+G7-G13 -> -27.42735 | H27: =H20+H7-H13 -> -51.219261 | I27: =I20+I7-I13 -> -46.229149 | J27: =J20+J7-J13 -> -49.910555 | K27: =K20+K7-K13 -> -43.204538 | ... M27: =M20+M7-M13 -> -49.077524
B29: Liquidity Ratios
B31: Current Ratio | D31: ='Balance Sheet'!C29/'Balance Sheet'!C55 -> 1.9083795 | E31: ='Balance Sheet'!D29/'Balance Sheet'!D55 -> 2.0104208 | F31: ='Balance Sheet'!E29/'Balance Sheet'!E55 -> 2.9601748 | G31: ='Balance Sheet'!F29/'Balance Sheet'!F55 -> 2.933673 | H31: ='Balance Sheet'!G29/'Balance Sheet'!G55 -> 2.6215167 | I31: ='Balance Sheet'!H29/'Balance Sheet'!H55 -> 2.8289369 | J31: ='Balance Sheet'!I29/'Balance Sheet'!I55 -> 2.8911703 | K31: ='Balance Sheet'!J29/'Balance Sheet'!J55 -> 3.2365755 | ... M31: ='Balance Sheet'!L29/'Balance Sheet'!L55 -> 3.2000217
B33: Quick Ratio | D33: =('Balance Sheet'!C29-'Balance Sheet'!C20)/'Balance Sheet'!C55 -> 1.7342041 | E33: =('Balance Sheet'!D29-'Balance Sheet'!D20)/'Balance Sheet'!D55 -> 1.8532039 | F33: =('Balance Sheet'!E29-'Balance Sheet'!E20)/'Balance Sheet'!E55 -> 2.7565465 | G33: =('Balance Sheet'!F29-'Balance Sheet'!F20)/'Balance Sheet'!F55 -> 2.703675 | H33: =('Balance Sheet'!G29-'Balance Sheet'!G20)/'Balance Sheet'!G55 -> 2.5061907 | I33: =('Balance Sheet'!H29-'Balance Sheet'!H20)/'Balance Sheet'!H55 -> 2.7365018 | J33: =('Balance Sheet'!I29-'Balance Sheet'!I20)/'Balance Sheet'!I55 -> 2.7629261 | K33: =('Balance Sheet'!J29-'Balance Sheet'!J20)/'Balance Sheet'!J55 -> 3.1348272 | ... M33: =('Balance Sheet'!L29-'Balance Sheet'!L20)/'Balance Sheet'!L55 -> 3.1060338
B35: Solvency Ratios
B37: D/E | D37: =('Balance Sheet'!C42+'Balance Sheet'!C48)/'Balance Sheet'!C38 -> 0.12863188 | E37: =('Balance Sheet'!D42+'Balance Sheet'!D48)/'Balance Sheet'!D38 -> 0.15714946 | F37: =('Balance Sheet'!E42+'Balance Sheet'!E48)/'Balance Sheet'!E38 -> 0.13013879 | G37: =('Balance Sheet'!F42+'Balance Sheet'!F48)/'Balance Sheet'!F38 -> 0.092901073 | H37: =('Balance Sheet'!G42+'Balance Sheet'!G48)/'Balance Sheet'!G38 -> 0.083623573 | I37: =('Balance Sheet'!H42+'Balance Sheet'!H48)/'Balance Sheet'!H38 -> 0.069972457 | J37: =('Balance Sheet'!I42+'Balance Sheet'!I48)/'Balance Sheet'!I38 -> 0.062496047 | K37: =('Balance Sheet'!J42+'Balance Sheet'!J48)/'Balance Sheet'!J38 -> 0.053623449 | ... M37: =('Balance Sheet'!L42+'Balance Sheet'!L48)/'Balance Sheet'!L38 -> 0.040670652
B39: Debt to Capital | D39: =('Balance Sheet'!C42+'Balance Sheet'!C48)/('Balance Sheet'!C38+'Balance Sheet'!C42+'Balance Sheet'!C48) -> 0.11397151 | E39: =('Balance Sheet'!D42+'Balance Sheet'!D48)/('Balance Sheet'!D38+'Balance Sheet'!D42+'Balance Sheet'!D48) -> 0.1358074 | F39: =('Balance Sheet'!E42+'Balance Sheet'!E48)/('Balance Sheet'!E38+'Balance Sheet'!E42+'Balance Sheet'!E48) -> 0.11515293 | G39: =('Balance Sheet'!F42+'Balance Sheet'!F48)/('Balance Sheet'!F38+'Balance Sheet'!F42+'Balance Sheet'!F48) -> 0.085004101 | H39: =('Balance Sheet'!G42+'Balance Sheet'!G48)/('Balance Sheet'!G38+'Balance Sheet'!G42+'Balance Sheet'!G48) -> 0.077170316 | I39: =('Balance Sheet'!H42+'Balance Sheet'!H48)/('Balance Sheet'!H38+'Balance Sheet'!H42+'Balance Sheet'!H48) -> 0.065396503 | J39: =('Balance Sheet'!I42+'Balance Sheet'!I48)/('Balance Sheet'!I38+'Balance Sheet'!I42+'Balance Sheet'!I48) -> 0.058820028 | K39: =('Balance Sheet'!J42+'Balance Sheet'!J48)/('Balance Sheet'!J38+'Balance Sheet'!J42+'Balance Sheet'!J48) -> 0.05089432 | ... M39: =('Balance Sheet'!L42+'Balance Sheet'!L48)/('Balance Sheet'!L38+'Balance Sheet'!L42+'Balance Sheet'!L48) -> 0.039081195
B41: Financial Leverage | D41: =U49/U51 -> 1.6047746 | E41: =V49/V51 -> 1.5357974 | F41: =W49/W51 -> 1.3922537 | G41: =X49/X51 -> 1.3563579 | H41: =Y49/Y51 -> 1.3714867
B43: Interest Coverage | D43: ='Income Statement '!B54/'Income Statement '!B63 -> 58.649869 | E43: ='Income Statement '!C54/'Income Statement '!C63 -> 28.470118 | F43: ='Income Statement '!D54/'Income Statement '!D63 -> 28.251593 | G43: ='Income Statement '!E54/'Income Statement '!E63 -> 38.125601 | H43: ='Income Statement '!F54/'Income Statement '!F63 -> 35.556136 | I43: ='Income Statement '!G54/'Income Statement '!G63 -> 35.234589 | J43: ='Income Statement '!H54/'Income Statement '!H63 -> 44.971075 | K43: ='Income Statement '!I54/'Income Statement '!I63 -> 49.20646 | ... M43: ='Income Statement '!K54/'Income Statement '!K63 -> 62.924103
B45: Profitability Ratios
B47: Gross Profit Margin | D47: ='Income Statement '!B19 -> 0.47320399 | E47: ='Income Statement '!C19 -> 0.54923566 | F47: ='Income Statement '!D19 -> 0.58567056 | G47: ='Income Statement '!E19 -> 0.54704534 | H47: ='Income Statement '!F19 -> 0.57120343 | I47: ='Income Statement '!G19 -> 0.5452718 | J47: ='Income Statement '!H19 -> 0.5452718 | K47: ='Income Statement '!I19 -> 0.5452718 | ... M47: ='Income Statement '!K19 -> 0.5452718 | T47: 2020 | U47: =T47+1 -> 2021 | V47: =U47+1 -> 2022 | W47: =V47+1 -> 2023 | X47: =W47+1 -> 2024 | Y47: =X47+1 -> 2025
S48: Asset | T48: ='Balance Sheet'!B31 -> 13327.38 | U48: ='Balance Sheet'!C31 -> 16118.1 | V48: ='Balance Sheet'!D31 -> 17613.94 | W48: ='Balance Sheet'!E31 -> 21012.26 | X48: ='Balance Sheet'!F31 -> 26585.24 | Y48: ='Balance Sheet'!G31 -> 31199.24
B49: EBITDA Margin | D49: ='Income Statement '!B54/'Income Statement '!B6 -> 0.3439717 | E49: ='Income Statement '!C54/'Income Statement '!C6 -> 0.25771685 | F49: ='Income Statement '!D54/'Income Statement '!D6 -> 0.28941678 | G49: ='Income Statement '!E54/'Income Statement '!E6 -> 0.27289366 | H49: ='Income Statement '!F54/'Income Statement '!F6 -> 0.26686181 | I49: ='Income Statement '!G54/'Income Statement '!G6 -> 0.24 | J49: ='Income Statement '!H54/'Income Statement '!H6 -> 0.24 | K49: ='Income Statement '!I54/'Income Statement '!I6 -> 0.24 | ... M49: ='Income Statement '!K54/'Income Statement '!K6 -> 0.24 | U49: =(T48+U48)/2 -> 14722.74 | V49: =(U48+V48)/2 -> 16866.02 | W49: =(V48+W48)/2 -> 19313.1 | X49: =(W48+X48)/2 -> 23798.75 | Y49: =(X48+Y48)/2 -> 28892.24
S50: Equity | T50: 8503.91 | U50: 9844.76 | V50: 12119.1 | W50: 15624.55 | X50: 19467.59 | Y50: 22665.14
B51: Operating Profit Margin | D51: ='Income Statement '!B55 -> 0.3439717 | E51: ='Income Statement '!C55 -> 0.25771685 | F51: ='Income Statement '!D55 -> 0.28941678 | G51: ='Income Statement '!E55 -> 0.27289366 | H51: ='Income Statement '!F55 -> 0.26686181 | I51: ='Income Statement '!G55 -> 0.24 | J51: ='Income Statement '!H55 -> 0.24 | K51: ='Income Statement '!I55 -> 0.24 | ... M51: ='Income Statement '!K55 -> 0.24 | U51: =(T50+U50)/2 -> 9174.335 | V51: =(U50+V50)/2 -> 10981.93 | W51: =(V50+W50)/2 -> 13871.825 | X51: =(W50+X50)/2 -> 17546.07 | Y51: =(X50+Y50)/2 -> 21066.365
S52: debt | T52: ='Balance Sheet'!B42+'Balance Sheet'!B48 -> 865.16 | U52: ='Balance Sheet'!C42+'Balance Sheet'!C48 -> 1266.35 | V52: ='Balance Sheet'!D42+'Balance Sheet'!D48 -> 1904.51 | W52: ='Balance Sheet'!E42+'Balance Sheet'!E48 -> 2033.36 | X52: ='Balance Sheet'!F42+'Balance Sheet'!F48 -> 1808.56 | Y52: ='Balance Sheet'!G42+'Balance Sheet'!G48 -> 1895.34
B53: Net Profit Margin | D53: ='Income Statement '!B86 -> 0.24873554 | E53: ='Income Statement '!C86 -> 0.14093356 | F53: ='Income Statement '!D86 -> 0.15512944 | G53: ='Income Statement '!E86 -> 0.15328499 | H53: ='Income Statement '!F86 -> 0.15362016 | I53: ='Income Statement '!G86 -> 0.13149583 | J53: ='Income Statement '!H86 -> 0.13290102 | K53: ='Income Statement '!I86 -> 0.13144111 | ... M53: ='Income Statement '!K86 -> 0.13310749 | U53: =(T52+U52)/2 -> 1065.755 | V53: =(U52+V52)/2 -> 1585.43 | W53: =(V52+W52)/2 -> 1968.935 | X53: =(W52+X52)/2 -> 1920.96 | Y53: =(X52+Y52)/2 -> 1851.95
S54: Capital | T54: =T50+T52 -> 9369.07 | U54: =U50+U52 -> 11111.11 | V54: =V50+V52 -> 14023.61 | W54: =W50+W52 -> 17657.91 | X54: =X50+X52 -> 21276.15 | Y54: =Y50+Y52 -> 24560.48
B55: ROE | D55: ='Income Statement '!B85/Ratios!U51 -> 0.3541085 | E55: ='Income Statement '!C85/Ratios!V51 -> 0.20400604 | F55: ='Income Statement '!D85/Ratios!W51 -> 0.21412539 | G55: ='Income Statement '!E85/Ratios!X51 -> 0.19784544 | H55: ='Income Statement '!F85/Ratios!Y51 -> 0.17680174 | I55: ='Income Statement '!G85/Ratios!Z51 -> #DIV/0! | J55: ='Income Statement '!H85/Ratios!AA51 -> #DIV/0! | K55: ='Income Statement '!I85/Ratios!AB51 -> #DIV/0! | ... M55: ='Income Statement '!K85/Ratios!AD51 -> #DIV/0! | U55: =(T54+U54)/2 -> 10240.09 | V55: =(U54+V54)/2 -> 12567.36 | W55: =(V54+W54)/2 -> 15840.76 | X55: =(W54+X54)/2 -> 19467.03 | Y55: =(X54+Y54)/2 -> 22918.315
B57: Ebit - Tax | D57: ='Income Statement '!B54-'Income Statement '!B83 -> 3903.34 | E57: ='Income Statement '!C54-'Income Statement '!C83 -> 3322.78 | F57: ='Income Statement '!D54-'Income Statement '!D83 -> 4503.74 | G57: ='Income Statement '!E54-'Income Statement '!E83 -> 4980.98 | H57: ='Income Statement '!F54-'Income Statement '!F83 -> 5216.33 | I57: ='Income Statement '!G54-'Income Statement '!G83 -> 4993.9652 | J57: ='Income Statement '!H54-'Income Statement '!H83 -> 6007.1785 | K57: ='Income Statement '!I54-'Income Statement '!I83 -> 6749.505 | ... M57: ='Income Statement '!K54-'Income Statement '!K83 -> 8460.0692
B59: Return On Total Capital | D59: =D57/((T54+U54)/2) -> 0.3811822 | E59: =E57/((U54+V54)/2) -> 0.26439761 | F59: =F57/((V54+W54)/2) -> 0.28431338 | G59: =G57/((W54+X54)/2) -> 0.25586748 | H59: =H57/((X54+Y54)/2) -> 0.2276053 | I59: =I57/((Y54+Z54)/2) -> 0.40666674 | J59: =J57/((Z54+AA54)/2) -> #DIV/0! | K59: =K57/((AA54+AB54)/2) -> #DIV/0! | ... M59: =M57/((AC54+AD54)/2) -> #DIV/0!
B61: Du Pont Analysis
...

Sheet Key Indicator
A1: Particulars | C1: 2021 | D1: =C1+1 -> 2022 | E1: =D1+1 -> 2023 | F1: =E1+1 -> 2024 | G1: =F1+1 -> 2025 | H1: =G1+1 -> 2026 | I1: =H1+1 -> 2027 | J1: =I1+1 -> 2028 | K1: =J1+1 -> 2029 | ... M1: =L1+1 -> 2031
A2: Revenue from Operations | C2: ='Income Statement '!B6 -> 13060.9 | D2: ='Income Statement '!C6 -> 15896.71 | E2: ='Income Statement '!D6 -> 19147.3 | F2: ='Income Statement '!E6 -> 22646.77 | G2: ='Income Statement '!F6 -> 24245.32 | H2: ='Income Statement '!G6 -> 25457.586 | I2: ='Income Statement '!H6 -> 30695.907 | J2: ='Income Statement '!I6 -> 34403.55 | ... M2: ='Income Statement '!L6 -> 0
A3: Revenue Growth | D3: =D2/C2-1 -> 0.2171221 | E3: =E2/D2-1 -> 0.20448193 | F3: =F2/E2-1 -> 0.18276572 | G3: =G2/F2-1 -> 0.070586225 | H3: =H2/G2-1 -> 0.05 | I3: =I2/H2-1 -> 0.2057666 | J3: =J2/I2-1 -> 0.12078623 | K3: =K2/J2-1 -> 0.12103659 | ... M3: =M2/L2-1 -> -1
A5: COGS | C5: ='Income Statement '!B16 -> 6880.43 | D5: ='Income Statement '!C16 -> 7165.67 | E5: ='Income Statement '!D16 -> 7933.29 | F5: ='Income Statement '!E16 -> 10257.96 | G5: ='Income Statement '!F16 -> 10396.31 | H5: ='Income Statement '!G16 -> 11576.282 | I5: ='Income Statement '!H16 -> 13958.295 | J5: ='Income Statement '!I16 -> 15644.264 | ... M5: ='Income Statement '!L16 -> 0
A6: COGS Growth | D6: =D5/C5-1 -> 0.041456711 | E6: =E5/D5-1 -> 0.10712467 | F6: =F5/E5-1 -> 0.29302723 | G6: =G5/F5-1 -> 0.013487087 | H6: =H5/G5-1 -> 0.11349915 | I6: =I5/H5-1 -> 0.2057666 | J6: =J5/I5-1 -> 0.12078623 | K6: =K5/J5-1 -> 0.12103659 | ... M6: =M5/L5-1 -> -1
A8: EBITDA | C8: ='Income Statement '!B54 -> 4492.58 | D8: ='Income Statement '!C54 -> 4096.85 | E8: ='Income Statement '!D54 -> 5541.55 | F8: ='Income Statement '!E54 -> 6180.16 | G8: ='Income Statement '!F54 -> 6470.15 | H8: ='Income Statement '!G54 -> 6109.8206 | I8: ='Income Statement '!H54 -> 7367.0176 | J8: ='Income Statement '!I54 -> 8256.8519 | ... M8: ='Income Statement '!L54 -> 0
A9: EBITDA Growth | D9: =D8/C8-1 -> -0.088085243 | E9: =E8/D8-1 -> 0.35263678 | F9: =F8/E8-1 -> 0.11524032 | G9: =G8/F8-1 -> 0.046922733 | H9: =H8/G8-1 -> -0.055691037 | I9: =I8/H8-1 -> 0.2057666 | J9: =J8/I8-1 -> 0.12078623 | K9: =K8/J8-1 -> 0.12103659 | ... M9: =M8/L8-1 -> -1
A11: Net Income | C11: ='Income Statement '!B85 -> 3248.71 | D11: ='Income Statement '!C85 -> 2240.38 | E11: ='Income Statement '!D85 -> 2970.31 | F11: ='Income Statement '!E85 -> 3471.41 | G11: ='Income Statement '!F85 -> 3724.57 | H11: ='Income Statement '!G85 -> 3347.5663 | I11: ='Income Statement '!H85 -> 4079.5174 | J11: ='Income Statement '!I85 -> 4522.0409 | ... M11: ='Income Statement '!L85 -> 0
A12: PAT Growth | D12: =D11/C11-1 -> -0.31037858 | E12: =E11/D11-1 -> 0.32580634 | F12: =F11/E11-1 -> 0.16870293 | G12: =G11/F11-1 -> 0.072927139 | H12: =H11/G11-1 -> -0.10122073 | I12: =I11/H11-1 -> 0.21865172 | J12: =J11/I11-1 -> 0.10847446 | K12: =K11/J11-1 -> 0.12701327 | ... M12: =M11/L11-1 -> -1
A14: Non Operating Income | C14: =-'Income Statement '!B78 -> -57.54 | D14: =-'Income Statement '!C78 -> -54.92 | E14: =-'Income Statement '!D78 -> -77.22 | F14: =-'Income Statement '!E78 -> 18.1 | G14: =-'Income Statement '!F78 -> 102.12 | H14: ='Income Statement '!G78 -> -105.81161 | I14: =SUM(I11:I13) -> 4079.7361 | J14: =SUM(J11:J13) -> 4522.1494 | K14: =SUM(K11:K13) -> 5096.5271 | L14: =SUM(L11:L13) -> 5756.372 | M14: =SUM(M11:M13) -> -1
A15: Non Operating Income Growth | D15: =D14/C14-1 -> -0.045533542 | E15: =E14/D14-1 -> 0.40604516 | F15: =F14/E14-1 -> -1.2343952 | G15: =G14/F14-1 -> 4.641989 | H15: =H14/G14-1 -> -2.0361497
A16: % of Sales | C16: =(C14/'Income Statement '!B6) -> -0.0044055157 | D16: =(D14/'Income Statement '!C6) -> -0.0034548029 | E16: =(E14/'Income Statement '!D6) -> -0.0040329446 | F16: =(F14/'Income Statement '!E6) -> 0.00079923097 | G16: =(G14/'Income Statement '!F6) -> 0.0042119469
A17: % of Net Income | C17: =C14/'Income Statement '!B85 -> -0.017711646 | D17: =D14/'Income Statement '!C85 -> -0.024513699 | E17: =E14/'Income Statement '!D85 -> -0.025997286 | F17: =F14/'Income Statement '!E85 -> 0.0052140197 | G17: =G14/'Income Statement '!F85 -> 0.02741793
A19: Interest Income | C19: =-'Income Statement '!B62 -> 60.03 | D19: =-'Income Statement '!C62 -> 34.85 | E19: =-'Income Statement '!D62 -> 58.12 | F19: =-'Income Statement '!E62 -> 136.59 | G19: =-'Income Statement '!F62 -> 202.66
A20: Cash and cash equivalents | C20: ='Balance Sheet'!C24 -> 1335.14 | D20: ='Balance Sheet'!D24 -> 396.74 | E20: ='Balance Sheet'!E24 -> 963.14 | F20: ='Balance Sheet'!F24 -> 1590.08 | G20: ='Balance Sheet'!G24 -> 2308.52
A21: Yields on Cash and cash equivalents | C21: =C19/C20 -> 0.044961577 | D21: =D19/D20 -> 0.087840903 | E21: =E19/E20 -> 0.060344291 | F21: =F19/F20 -> 0.085901338 | G21: =G19/G20 -> 0.087787847
A23: Interest Expense | C23: ='Income Statement '!B63 -> 76.6 | D23: ='Income Statement '!C63 -> 143.9 | E23: ='Income Statement '!D63 -> 196.15 | F23: ='Income Statement '!E63 -> 162.1 | G23: ='Income Statement '!F63 -> 181.97
A24: Total Debt | C24: ='Balance Sheet'!C42+'Balance Sheet'!C48 -> 1266.35 | D24: ='Balance Sheet'!D42+'Balance Sheet'!D48 -> 1904.51 | E24: ='Balance Sheet'!E42+'Balance Sheet'!E48 -> 2033.36 | F24: ='Balance Sheet'!F42+'Balance Sheet'!F48 -> 1808.56 | G24: ='Balance Sheet'!G42+'Balance Sheet'!G48 -> 1895.34
A25: Interest Expense as % of Total Debt | C25: =C23/C24 -> 0.060488806 | D25: =D23/D24 -> 0.075557492 | E25: =E23/E24 -> 0.096465948 | F25: =F23/F24 -> 0.089629318 | G25: =G23/G24 -> 0.096009159
A27: Miscellaneous Expenses | C27: ='Income Statement '!B77 -> 140.49 | D27: ='Income Statement '!C77 -> 99.17 | E27: ='Income Statement '!D77 -> 166.27 | F27: ='Income Statement '!E77 -> 185.46 | G27: ='Income Statement '!F77 -> 202.04
A28: Other Expenses | C28: ='Income Statement '!B46 -> - | D28: ='Income Statement '!C46 -> 2.38 | E28: ='Income Statement '!D46 -> 1.34 | F28: ='Income Statement '!E46 -> - | G28: ='Income Statement '!F46 -> -
A29: Operating Profit (EBIT) | C29: ='Income Statement '!B54 -> 4492.58 | D29: ='Income Statement '!C54 -> 4096.85 | E29: ='Income Statement '!D54 -> 5541.55 | F29: ='Income Statement '!E54 -> 6180.16 | G29: ='Income Statement '!F54 -> 6470.15
A30: Miscellaneous Expenses as % of Sales | C30: =C27/'Income Statement '!B4 -> 0.010756533 | D30: =D27/'Income Statement '!C4 -> 0.0062383978 | E30: =E27/'Income Statement '!D4 -> 0.0086837309 | F30: =F27/'Income Statement '!E4 -> 0.0081892473 | G30: =G27/'Income Statement '!F4 -> 0.0083331546
A31: Miscellaneous Expenses as % of Operating Profit | C31: =C27/'Key Indicator'!C29 -> 0.031271563 | D31: =D27/'Key Indicator'!D29 -> 0.024206402 | E31: =E27/'Key Indicator'!E29 -> 0.030004241 | F31: =F27/'Key Indicator'!F29 -> 0.030008932 | G31: =G27/'Key Indicator'!G29 -> 0.031226479
A32: Other Expenses as % of Operating Profit
A34: Advertisement Expenses | C34: - | D34: - | E34: - | F34: - | G34: -
A35: Revenue
A36: Advertisement Expenses as % of Sales
A38: Executive Compensation (Including all Key Personnel) | C38: 111.27 | D38: 730.1 | E38: 160.25 | F38: 1826.94 | G38: 584.89
A39: Net Profit | C39: ='Income Statement '!B85 -> 3248.71 | D39: ='Income Statement '!C85 -> 2240.38 | E39: ='Income Statement '!D85 -> 2970.31 | F39: ='Income Statement '!E85 -> 3471.41 | G39: ='Income Statement '!F85 -> 3724.57
A40: Executive Compensation as % of Profit | C40: =C38/C39 -> 0.034250518 | D40: =D38/D39 -> 0.32588222 | E40: =E38/E39 -> 0.053950598 | F40: =F38/F39 -> 0.52628183 | G40: =G38/G39 -> 0.15703558
